<?xml version="1.0" encoding="utf-8"?><testsuite errors="0" failures="0" name="pytest" skips="0" tests="4" time="0.291"><testcase classname="pyoad.tests.test_main" file="pyoad/tests/test_main.py" line="17" name="test_mini_instance_def" time="0.026260852813720703"><system-out>[6161] Object daemon started in : /home/travis/virtualenv/python3.5.6/bin/python
hello, world!
[6161] Object daemon  was asked to exit - closing communication connection
[6161] Object daemon  terminating
</system-out></testcase><testcase classname="pyoad.tests.test_main" file="pyoad/tests/test_main.py" line="23" name="test_mini_instance_def_primitives" time="0.021535396575927734"><system-out>[6163] Object daemon started in : /home/travis/virtualenv/python3.5.6/bin/python
hello, world!
</system-out></testcase><testcase classname="pyoad.tests.test_main" file="pyoad/tests/test_main.py" line="29" name="test_mini_instance" time="0.024104833602905273"><system-out>[6163] Object daemon  was asked to exit - closing communication connection
[6163] Object daemon  terminating
[6165] Object daemon started in : /home/travis/virtualenv/python3.5.6/bin/python
hello, world!
Explicit str required: hello, world!
With str formatting:  hello, world!  
Explicit repr: ObjectDaemonProxy&lt;&apos;hello, world!&apos;&gt;
Subscript: hello
</system-out><system-err>Exception ignored in: &lt;bound method ObjectDaemonProxy.__del__ of ObjectDaemonProxy&lt;not started&gt;&gt;
Traceback (most recent call last):
  File &quot;/home/travis/build/smarie/python-object-as-daemon/pyoad/main.py&quot;, line 271, in __del__
    self.terminate_daemon()
  File &quot;/home/travis/build/smarie/python-object-as-daemon/pyoad/main.py&quot;, line 287, in terminate_daemon
    self.p.join(timeout=10000)
  File &quot;/opt/python/3.5.6/lib/python3.5/multiprocessing/process.py&quot;, line 122, in join
    assert self._parent_pid == os.getpid(), &apos;can only join a child process&apos;
AssertionError: can only join a child process
</system-err></testcase><testcase classname="pyoad.tests.test_main" file="pyoad/tests/test_main.py" line="76" name="test_main" time="0.053772926330566406"><system-out>Creating Test virtual environment with conda: conda create --prefix /home/travis/build/smarie/python-object-as-daemon/tmp_venv/tmp python=3.5.0 --yes
Conda does not seem to be available. Creating Test virtual environment with venv (selected version number will be ignored): python - m venv /home/travis/build/smarie/python-object-as-daemon/tmp_venv/tmp
Test virtual environment created
Test virtual environment is venv
local test
daemon test
[6165] Object daemon  was asked to exit - closing communication connection
[6165] Object daemon  terminating
[6169] Object daemon started in : /home/travis/virtualenv/python3.5.6/bin/python
[6169] Object daemon  was asked to exit - closing communication connection
[6169] Object daemon  terminating
tearing down
process psutil.Process(pid=6165, status=&apos;terminated&apos;) terminated with exit code 0
DONE
</system-out><system-err>Unknown option: - 
usage: python [option] ... [-c cmd | -m mod | file | -] [arg] ...
Try `python -h&apos; for more information.
Exception ignored in: &lt;object repr() failed&gt;
Traceback (most recent call last):
  File &quot;/home/travis/build/smarie/python-object-as-daemon/pyoad/main.py&quot;, line 271, in __del__
    self.terminate_daemon()
  File &quot;/home/travis/build/smarie/python-object-as-daemon/pyoad/main.py&quot;, line 279, in terminate_daemon
    self.remote_call_using_pipe(EXIT_CMD)
  File &quot;/home/travis/build/smarie/python-object-as-daemon/pyoad/main.py&quot;, line 242, in remote_call_using_pipe
    self.parent_conn.send((cmd_type, meth_or_attr_name, args, kwargs))
  File &quot;/opt/python/3.5.6/lib/python3.5/multiprocessing/connection.py&quot;, line 206, in send
    self._send_bytes(ForkingPickler.dumps(obj))
  File &quot;/opt/python/3.5.6/lib/python3.5/multiprocessing/connection.py&quot;, line 404, in _send_bytes
    self._send(header + buf)
  File &quot;/opt/python/3.5.6/lib/python3.5/multiprocessing/connection.py&quot;, line 368, in _send
    n = write(self._handle, buf)
BrokenPipeError: [Errno 32] Broken pipe
Exception ignored in: &lt;bound method ObjectDaemonProxy.__del__ of ObjectDaemonProxy&lt;not started&gt;&gt;
Traceback (most recent call last):
  File &quot;/home/travis/build/smarie/python-object-as-daemon/pyoad/main.py&quot;, line 271, in __del__
    self.terminate_daemon()
  File &quot;/home/travis/build/smarie/python-object-as-daemon/pyoad/main.py&quot;, line 287, in terminate_daemon
    self.p.join(timeout=10000)
  File &quot;/opt/python/3.5.6/lib/python3.5/multiprocessing/process.py&quot;, line 122, in join
    assert self._parent_pid == os.getpid(), &apos;can only join a child process&apos;
AssertionError: can only join a child process
</system-err></testcase></testsuite>